Workbook
Name Slicer_Product_Type: #N/A
Name Slicer_Sales_Channel: #N/A
Name Slicer_State: #N/A
Name Slicer_Supplier: #N/A

Sheet Poultry dataset
A1: Order_ID | B1: Date | C1: Delivery_Date | D1: Product_Type | E1: Quantity_Ordered | F1: Unit_Selling_Price_NGN | G1: Discount_Percent | H1: Revenue_NGN | I1: Supplier | J1: Unit_Purchase_Cost_NGN | K1: Procurement_Cost_NGN | L1: Transport_Cost_NGN | M1: Handling_Cost_NGN | N1: Other_Cost_NGN | O1: Total_Cost_NGN | P1: Gross_Profit_NGN | Q1: Net_Profit_NGN | R1: Payment_Status | S1: Payment_Received_NGN | T1: Balance_Due_NGN | U1: Delivery_Status | V1: Sales_Channel | W1: Customer_Type | X1: State | Y1: Region | Z1: Estimated_Mortality_Percent | AA1: Computed_Net_Profit_NGN | AB1: Profit_Margin_Percent | AC1: Net_Profit_Reconciliation_NGN | AD1: Order_Year | AE1: Order_Month_Number | AF1: Order_Month | AG1: Order_YearMonth
A2: FZ00001 | B2: 45500 | C2: 45513 | D2: Broiler DOC | E2: 200 | F2: 808.71 | G2: 0.48 | H2: 160965.64 | I2: Farm Support | J2: 704.95 | K2: 140990 | L2: 3237.59 | M2: 588.73 | N2: 1046.45 | O2: 145862.77 | P2: 19975.64 | Q2: 15102.87 | R2: Paid | S2: 160965.64 | T2: 0 | U2: Delivered | V2: WhatsApp | W2: Commercial Farm | X2: Gombe | Y2: North East | Z2: 0.69 | AA2: =ROUND(H2-O2,2) -> 15102.87 | AB2: =AA2/H2 -> 0.09382667 | AC2: =ROUND(AA2-Q2,2) -> 0 | AD2: 2024 | AE2: 7 | AF2: July | AG2: 2024-07
A3: FZ00002 | B3: 45415 | C3: 45416 | D3: Pullet DOC | E3: 300 | F3: 1206.47 | G3: 2.13 | H3: 354231.66 | I3: AgroPlus NG | J3: 977.68 | K3: 293304 | L3: 7055.13 | M3: 1080.55 | N3: 2583.9 | O3: 304023.58 | P3: 60927.66 | Q3: 50208.08 | R3: Paid | S3: 354231.66 | T3: 0 | U3: Collected | V3: Phone Call | W3: Smallholder Farmer | X3: Kaduna | Y3: North West | Z3: 0.11 | AA3: =ROUND(H3-O3,2) -> 50208.08 | AB3: =AA3/H3 -> 0.14173798 | AC3: =ROUND(AA3-Q3,2) -> 0 | AD3: 2024 | AE3: 5 | AF3: May | AG3: 2024-05
A4: FZ00003 | B4: 45519 | C4: 45520 | D4: Broiler DOC | E4: 250 | F4: 901.18 | G4: 1.18 | H4: 222636.52 | I4: CHI FARMS | J4: 671.24 | K4: 167810 | L4: 5685.82 | M4: 1276.01 | N4: 6421.4 | O4: 181193.23 | P4: 54826.52 | Q4: 41443.29 | R4: Paid | S4: 222636.52 | T4: 0 | U4: Collected | V4: Walk-in | W4: Agro-dealer | X4: Enugu | Y4: South East | Z4: 0.33 | AA4: =ROUND(H4-O4,2) -> 41443.29 | AB4: =AA4/H4 -> 0.18614776 | AC4: =ROUND(AA4-Q4,2) -> 0 | AD4: 2024 | AE4: 8 | AF4: August | AG4: 2024-08
A5: FZ00004 | B5: 45873 | C5: 45885 | D5: Cockerel DOC | E5: 200 | F5: 749.22 | G5: 1.2 | H5: 148045.87 | I5: Farm Support | J5: 608.83 | K5: 121766 | L5: 1885.03 | M5: 1055.04 | N5: 5105.53 | O5: 129811.6 | P5: 26279.87 | Q5: 18234.27 | R5: Part-paid | S5: 76965.99 | T5: 71079.88 | U5: Collected | V5: Phone Call | W5: Smallholder Farmer | X5: Delta | Y5: South South | Z5: 1.53 | AA5: =ROUND(H5-O5,2) -> 18234.27 | AB5: =AA5/H5 -> 0.12316635 | AC5: =ROUND(AA5-Q5,2) -> 0 | AD5: 2025 | AE5: 8 | AF5: August | AG5: 2025-08
A6: FZ00005 | B6: 45870 | C6: 45872 | D6: Cockerel DOC | E6: 500 | F6: 758.41 | G6: 2.98 | H6: 367904.69 | I6: Farm Support | J6: 602.65 | K6: 301325 | L6: 2699.99 | M6: 1770.62 | N6: 3487.18 | O6: 309282.79 | P6: 66579.69 | Q6: 58621.9 | R6: Paid | S6: 367904.69 | T6: 0 | U6: Delivered | V6: WhatsApp | W6: Commercial Farm | X6: Jigawa | Y6: North West | Z6: 0.06 | AA6: =ROUND(H6-O6,2) -> 58621.9 | AB6: =AA6/H6 -> 0.15933991 | AC6: =ROUND(AA6-Q6,2) -> 0 | AD6: 2025 | AE6: 8 | AF6: August | AG6: 2025-08
A7: FZ00006 | B7: 45787 | D7: Noiler DOC | E7: 150 | F7: 994.92 | G7: 2.22 | H7: 145924.92 | I7: AgroPlus NG | J7: 781.98 | K7: 117297 | L7: 1733.25 | M7: 563.97 | N7: 7560.43 | O7: 127154.65 | P7: 28627.92 | Q7: 18770.27 | R7: Paid | S7: 145924.92 | T7: 0 | U7: Pending | V7: WhatsApp | W7: Distributor | X7: Kogi | Y7: North Central | Z7: 2.25 | AA7: =ROUND(H7-O7,2) -> 18770.27 | AB7: =AA7/H7 -> 0.12862964 | AC7: =ROUND(AA7-Q7,2) -> 0 | AD7: 2025 | AE7: 5 | AF7: May | AG7: 2025-05
A8: FZ00007 | B8: 45628 | D8: Broiler DOC | E8: 250 | F8: 974.17 | G8: 1.76 | H8: 239256.15 | I8: PAN Industries | J8: 727.3 | K8: 181825 | L8: 5720.86 | M8: 563.44 | N8: 510.45 | O8: 188619.75 | P8: 57431.15 | Q8: 50636.4 | R8: Paid | S8: 239256.15 | T8: 0 | U8: Pending | V8: Reseller | W8: Agro-dealer | X8: Ebonyi | Y8: South East | Z8: 1.25 | AA8: =ROUND(H8-O8,2) -> 50636.4 | AB8: =AA8/H8 -> 0.21164095 | AC8: =ROUND(AA8-Q8,2) -> 0 | AD8: 2024 | AE8: 12 | AF8: December | AG8: 2024-12
A9: FZ00008 | B9: 45318 | C9: 45331 | D9: Pullet DOC | E9: 500 | F9: 1181.27 | G9: 3.64 | H9: 569135.89 | I9: CHI FARMS | J9: 970.22 | K9: 485110 | L9: 7413.03 | M9: 1134.39 | N9: 6338.15 | O9: 499995.57 | P9: 84025.89 | Q9: 69140.32 | R9: Paid | S9: 569135.89 | T9: 0 | U9: Delivered | V9: Social Media | W9: Smallholder Farmer | X9: Ekiti | Y9: South West | Z9: 1.98 | AA9: =ROUND(H9-O9,2) -> 69140.32 | AB9: =AA9/H9 -> 0.12148297 | AC9: =ROUND(AA9-Q9,2) -> 0 | AD9: 2024 | AE9: 1 | AF9: January | AG9: 2024-01
A10: FZ00009 | B10: 45746 | C10: 45756 | D10: Broiler DOC | E10: 750 | F10: 836.85 | G10: 2.67 | H10: 610879.58 | I10: PAN Industries | J10: 673.75 | K10: 505312.5 | L10: 17584.67 | M10: 2579.18 | N10: 5762.05 | O10: 531238.4 | P10: 105567.08 | Q10: 79641.18 | R10: Paid | S10: 610879.58 | T10: 0 | U10: Delivered | V10: Phone Call | W10: Agro-dealer | X10: Enugu | Y10: South East | Z10: 2.01 | AA10: =ROUND(H10-O10,2) -> 79641.18 | AB10: =AA10/H10 -> 0.13037132 | AC10: =ROUND(AA10-Q10,2) -> 0 | AD10: 2025 | AE10: 3 | AF10: March | AG10: 2025-03
A11: FZ00010 | B11: 45779 | C11: 45788 | D11: Pullet DOC | E11: 300 | F11: 1318.81 | G11: 0.21 | H11: 394812.15 | I11: AgroPlus NG | J11: 1052.84 | K11: 315852 | L11: 4252.58 | M11: 1554.06 | N11: 11598.95 | O11: 333257.59 | P11: 78960.15 | Q11: 61554.56 | R11: Paid | S11: 394812.15 | T11: 0 | U11: Delivered | V11: WhatsApp | W11: Smallholder Farmer | X11: Oyo | Y11: South West | Z11: 1.45 | AA11: =ROUND(H11-O11,2) -> 61554.56 | AB11: =AA11/H11 -> 0.15590847 | AC11: =ROUND(AA11-Q11,2) -> 0 | AD11: 2025 | AE11: 5 | AF11: May | AG11: 2025-05
A12: FZ00011 | B12: 45818 | C12: 45818 | D12: Broiler DOC | E12: 200 | F12: 823.5 | G12: 2.33 | H12: 160862.49 | I12: CHI FARMS | J12: 718.26 | K12: 143652 | L12: 2326.27 | M12: 502.84 | N12: 3897.48 | O12: 150378.59 | P12: 17210.49 | Q12: 10483.9 | R12: Paid | S12: 160862.49 | T12: 0 | U12: Delivered | V12: WhatsApp | W12: Smallholder Farmer | X12: Katsina | Y12: North West | Z12: 1.79 | AA12: =ROUND(H12-O12,2) -> 10483.9 | AB12: =AA12/H12 -> 0.065173056 | AC12: =ROUND(AA12-Q12,2) -> 0 | AD12: 2025 | AE12: 6 | AF12: June | AG12: 2025-06
A13: FZ00012 | B13: 45638 | C13: 45643 | D13: Pullet DOC | E13: 200 | F13: 1396.14 | G13: 2.4 | H13: 272526.53 | I13: AgroPlus NG | J13: 1049.81 | K13: 209962 | L13: 3616.53 | M13: 816.72 | N13: 6360.06 | O13: 220755.31 | P13: 62564.53 | Q13: 51771.22 | R13: Paid | S13: 272526.53 | T13: 0 | U13: Delivered | V13: Referral | W13: Agro-dealer | X13: Ebonyi | Y13: South East | Z13: 1.66 | AA13: =ROUND(H13-O13,2) -> 51771.22 | AB13: =AA13/H13 -> 0.18996763 | AC13: =ROUND(AA13-Q13,2) -> 0 | AD13: 2024 | AE13: 12 | AF13: December | AG13: 2024-12
A14: FZ00013 | B14: 45309 | C14: 45323 | D14: Pullet DOC | E14: 100 | F14: 1284.14 | G14: 0.74 | H14: 127463.74 | I14: AgroPlus NG | J14: 983.7 | K14: 98370 | L14: 914.24 | M14: 405.52 | N14: 5571.93 | O14: 105261.69 | P14: 29093.74 | Q14: 22202.05 | R14: Paid | S14: 127463.74 | T14: 0 | U14: Collected | V14: Phone Call | W14: Smallholder Farmer | X14: Lagos | Y14: South West | Z14: 1.45 | AA14: =ROUND(H14-O14,2) -> 22202.05 | AB14: =AA14/H14 -> 0.17418326 | AC14: =ROUND(AA14-Q14,2) -> 0 | AD14: 2024 | AE14: 1 | AF14: January | AG14: 2024-01
A15: FZ00014 | B15: 45673 | D15: Noiler DOC | E15: 100 | F15: 947.09 | G15: 1.98 | H15: 0 | I15: CHI FARMS | J15: 714.98 | K15: 0 | L15: 0 | M15: 0 | N15: 0 | O15: 0 | P15: 0 | Q15: 0 | R15: Paid | S15: 0 | T15: 0 | U15: Cancelled | V15: Reseller | W15: Agro-dealer | X15: Ekiti | Y15: South West | Z15: 2.09 | AA15: =ROUND(H15-O15,2) -> 0 | AB15: =AA15/H15 -> #DIV/0! | AC15: =ROUND(AA15-Q15,2) -> 0 | AD15: 2025 | AE15: 1 | AF15: January | AG15: 2025-01
A16: FZ00015 | B16: 45382 | C16: 45392 | D16: Broiler DOC | E16: 250 | F16: 897.32 | G16: 1.54 | H16: 220875.32 | I16: Farm Support | J16: 734.71 | K16: 183677.5 | L16: 4398.8 | M16: 554.63 | N16: 531.3 | O16: 189162.23 | P16: 37197.82 | Q16: 31713.09 | R16: Paid | S16: 220875.32 | T16: 0 | U16: Delivered | V16: WhatsApp | W16: Smallholder Farmer | X16: Jigawa | Y16: North West | Z16: 1.59 | AA16: =ROUND(H16-O16,2) -> 31713.09 | AB16: =AA16/H16 -> 0.14357915 | AC16: =ROUND(AA16-Q16,2) -> 0 | AD16: 2024 | AE16: 3 | AF16: March | AG16: 2024-03
A17: FZ00016 | B17: 45682 | C17: 45691 | D17: Broiler DOC | E17: 300 | F17: 827.26 | G17: 1.47 | H17: 244529.78 | I17: AgroPlus NG | J17: 748.68 | K17: 224604 | L17: 2951.24 | M17: 1384.84 | N17: 6632.79 | O17: 235572.87 | P17: 19925.78 | Q17: 8956.91 | R17: Paid | S17: 244529.78 | T17: 0 | U17: Delivered | V17: Social Media | W17: Commercial Farm | X17: Kogi | Y17: North Central | Z17: 2.47 | AA17: =ROUND(H17-O17,2) -> 8956.91 | AB17: =AA17/H17 -> 0.036629117 | AC17: =ROUND(AA17-Q17,2) -> 0 | AD17: 2025 | AE17: 1 | AF17: January | AG17: 2025-01
A18: FZ00017 | B18: 45478 | C18: 45487 | D18: Broiler DOC | E18: 50 | F18: 831.37 | G18: 0.28 | H18: 41452.11 | I18: CHI FARMS | J18: 648.63 | K18: 32431.5 | L18: 1170.22 | M18: 257.65 | N18: 9685.54 | O18: 43544.91 | P18: 9020.61 | Q18: -2092.8 | R18: Paid | S18: 41452.11 | T18: 0 | U18: Delivered | V18: WhatsApp | W18: Distributor | X18: Ogun | Y18: South West | Z18: 1.63 | AA18: =ROUND(H18-O18,2) -> -2092.8 | AB18: =AA18/H18 -> -0.050487177 | AC18: =ROUND(AA18-Q18,2) -> 0 | AD18: 2024 | AE18: 7 | AF18: July | AG18: 2024-07
A19: FZ00018 | B19: 45415 | C19: 45422 | D19: Broiler DOC | E19: 500 | F19: 816.16 | G19: 2.04 | H19: 399755.17 | I19: AgroPlus NG | J19: 737.65 | K19: 368825 | L19: 6247.5 | M19: 2228.46 | N19: 4425.55 | O19: 381726.51 | P19: 30930.17 | Q19: 18028.66 | R19: Paid | S19: 399755.17 | T19: 0 | U19: Collected | V19: Referral | W19: Smallholder Farmer | X19: Anambra | Y19: South East | Z19: 0.42 | AA19: =ROUND(H19-O19,2) -> 18028.66 | AB19: =AA19/H19 -> 0.045099254 | AC19: =ROUND(AA19-Q19,2) -> 0 | AD19: 2024 | AE19: 5 | AF19: May | AG19: 2024-05
A20: FZ00019 | B20: 45606 | C20: 45609 | D20: Broiler DOC | E20: 1000 | F20: 874.45 | G20: 1.21 | H20: 863869.16 | I20: PAN Industries | J20: 714.27 | K20: 714270 | L20: 18845.96 | M20: 2352.97 | N20: 8698.96 | O20: 744167.89 | P20: 149599.16 | Q20: 119701.27 | R20: Paid | S20: 863869.16 | T20: 0 | U20: Collected | V20: Social Media | W20: Smallholder Farmer | X20: Osun | Y20: South West | Z20: 0.63 | AA20: =ROUND(H20-O20,2) -> 119701.27 | AB20: =AA20/H20 -> 0.13856412 | AC20: =ROUND(AA20-Q20,2) -> 0 | AD20: 2024 | AE20: 11 | AF20: November | AG20: 2024-11
A21: FZ00020 | B21: 45920 | C21: 45923 | D21: Noiler DOC | E21: 100 | F21: 1003.33 | G21: 1.86 | H21: 98466.81 | I21: Farm Support | J21: 738.3 | K21: 73830 | L21: 2124.59 | M21: 194.49 | N21: 1337.38 | O21: 77486.46 | P21: 24636.81 | Q21: 20980.35 | R21: Paid | S21: 98466.81 | T21: 0 | U21: Collected | V21: WhatsApp | W21: Commercial Farm | X21: Lagos | Y21: South West | Z21: 0.04 | AA21: =ROUND(H21-O21,2) -> 20980.35 | AB21: =AA21/H21 -> 0.21307027 | AC21: =ROUND(AA21-Q21,2) -> 0 | AD21: 2025 | AE21: 9 | AF21: September | AG21: 2025-09
A22: FZ00021 | B22: 45970 | C22: 45982 | D22: Broiler DOC | E22: 1200 | F22: 874.82 | G22: 0.11 | H22: 1048629.2 | I22: AgroPlus NG | J22: 735.28 | K22: 882336 | L22: 12192.83 | M22: 6917.1 | N22: 11134.45 | O22: 912580.38 | P22: 166293.24 | Q22: 136048.86 | R22: Unpaid | S22: 0 | T22: 1048629.2 | U22: Collected | V22: Walk-in | W22: Distributor | X22: Ekiti | Y22: South West | Z22: 2.43 | AA22: =ROUND(H22-O22,2) -> 136048.86 | AB22: =AA22/H22 -> 0.12973972 | AC22: =ROUND(AA22-Q22,2) -> 0 | AD22: 2025 | AE22: 11 | AF22: November | AG22: 2025-11
A23: FZ00022 | B23: 45664 | C23: 45665 | D23: Broiler DOC | E23: 300 | F23: 896.7 | G23: 1.72 | H23: 264383.03 | I23: CHI FARMS | J23: 673.4 | K23: 202020 | L23: 2285.45 | M23: 464.2 | N23: 5447.46 | O23: 210217.11 | P23: 62363.03 | Q23: 54165.92 | R23: Paid | S23: 264383.03 | T23: 0 | U23: Delivered | V23: Reseller | W23: Distributor | X23: Oyo | Y23: South West | Z23: 1.17 | AA23: =ROUND(H23-O23,2) -> 54165.92 | AB23: =AA23/H23 -> 0.20487669 | AC23: =ROUND(AA23-Q23,2) -> 0 | AD23: 2025 | AE23: 1 | AF23: January | AG23: 2025-01
A24: FZ00023 | B24: 45586 | D24: Noiler DOC | E24: 200 | F24: 956.04 | G24: 2.16 | H24: 187077.91 | I24: AgroPlus NG | J24: 767.29 | K24: 153458 | L24: 2593.91 | M24: 679.01 | N24: 9353.25 | O24: 166084.17 | P24: 33619.91 | Q24: 20993.74 | R24: Paid | S24: 187077.91 | T24: 0 | U24: Pending | V24: Walk-in | W24: Agro-dealer | X24: Ekiti | Y24: South West | Z24: 2.48 | AA24: =ROUND(H24-O24,2) -> 20993.74 | AB24: =AA24/H24 -> 0.11221924 | AC24: =ROUND(AA24-Q24,2) -> 0 | AD24: 2024 | AE24: 10 | AF24: October | AG24: 2024-10
A25: FZ00024 | B25: 45875 | C25: 45876 | D25: Broiler DOC | E25: 100 | F25: 866.88 | G25: 1.73 | H25: 85188.3 | I25: Farm Support | J25: 694.6 | K25: 69460 | L25: 1107.83 | M25: 192.58 | N25: 9430.34 | O25: 80190.75 | P25: 15728.3 | Q25: 4997.55 | R25: Paid | S25: 85188.3 | T25: 0 | U25: Collected | V25: Referral | W25: New Customer | X25: Kebbi | Y25: North West | Z25: 0.12 | AA25: =ROUND(H25-O25,2) -> 4997.55 | AB25: =AA25/H25 -> 0.058664746 | AC25: =ROUND(AA25-Q25,2) -> 0 | AD25: 2025 | AE25: 8 | AF25: August | AG25: 2025-08
A26: FZ00025 | B26: 45419 | C26: 45433 | D26: Noiler DOC | E26: 150 | F26: 985.57 | G26: 0.7 | H26: 146800.65 | I26: AgroPlus NG | J26: 757.53 | K26: 113629.5 | L26: 3511.42 | M26: 397.76 | N26: 10539.36 | O26: 128078.04 | P26: 33171.15 | Q26: 18722.61 | R26: Paid | S26: 146800.65 | T26: 0 | U26: Delivered | V26: WhatsApp | W26: Commercial Farm | X26: Gombe | Y26: North East | Z26: 0.96 | AA26: =ROUND(H26-O26,2) -> 18722.61 | AB26: =AA26/H26 -> 0.12753765 | AC26: =ROUND(AA26-Q26,2) -> 0 | AD26: 2024 | AE26: 5 | AF26: May | AG26: 2024-05
A27: FZ00026 | B27: 45879 | C27: 45879 | D27: Broiler DOC | E27: 250 | F27: 893.98 | G27: 0.96 | H27: 221349.45 | I27: AgroPlus NG | J27: 726.94 | K27: 181735 | L27: 2069.76 | M27: 816.06 | N27: 10711.01 | O27: 195331.83 | P27: 39614.45 | Q27: 26017.62 | R27: Paid | S27: 221349.45 | T27: 0 | U27: Delivered | V27: WhatsApp | W27: Commercial Farm | X27: Bayelsa | Y27: South South | Z27: 1.55 | AA27: =ROUND(H27-O27,2) -> 26017.62 | AB27: =AA27/H27 -> 0.11754093 | AC27: =ROUND(AA27-Q27,2) -> 0 | AD27: 2025 | AE27: 8 | AF27: August | AG27: 2025-08
A28: FZ00027 | B28: 45463 | D28: Broiler DOC | E28: 300 | F28: 832.89 | G28: 0.66 | H28: 248217.88 | I28: PAN Industries | J28: 659.94 | K28: 197982 | L28: 4803.96 | M28: 1256.77 | N28: 2373.76 | O28: 206416.49 | P28: 50235.88 | Q28: 41801.39 | R28: Unpaid | S28: 0 | T28: 248217.88 | U28: Pending | V28: Walk-in | W28: Distributor | X28: Sokoto | Y28: North West | Z28: 1.33 | AA28: =ROUND(H28-O28,2) -> 41801.39 | AB28: =AA28/H28 -> 0.16840604 | AC28: =ROUND(AA28-Q28,2) -> 0 | AD28: 2024 | AE28: 6 | AF28: June | AG28: 2024-06
A29: FZ00028 | B29: 45852 | C29: 45859 | D29: Broiler DOC | E29: 50 | F29: 906.03 | G29: 2.2 | H29: 44304.87 | I29: PAN Industries | J29: 671.95 | K29: 33597.5 | L29: 264.61 | M29: 95.03 | N29: 9747.92 | O29: 43705.06 | P29: 10707.37 | Q29: 599.81 | R29: Part-paid | S29: 24041.37 | T29: 20263.5 | U29: Delivered | V29: WhatsApp | W29: New Customer | X29: Edo | Y29: South South | Z29: 1.52 | AA29: =ROUND(H29-O29,2) -> 599.81 | AB29: =AA29/H29 -> 0.013538241 | AC29: =ROUND(AA29-Q29,2) -> 0 | AD29: 2025 | AE29: 7 | AF29: July | AG29: 2025-07
A30: FZ00029 | B30: 45862 | C30: 45868 | D30: Broiler DOC | E30: 300 | F30: 870.02 | G30: 2.08 | H30: 255577.08 | I30: PAN Industries | J30: 656.96 | K30: 197088 | L30: 6174.06 | M30: 1041.36 | N30: 2514.43 | O30: 206817.85 | P30: 58489.08 | Q30: 48759.23 | R30: Paid | S30: 255577.08 | T30: 0 | U30: Delivered | V30: Social Media | W30: Smallholder Farmer | X30: Kogi | Y30: North Central | Z30: 1.69 | AA30: =ROUND(H30-O30,2) -> 48759.23 | AB30: =AA30/H30 -> 0.19078092 | AC30: =ROUND(AA30-Q30,2) -> 0 | AD30: 2025 | AE30: 7 | AF30: July | AG30: 2025-07
A31: FZ00030 | B31: 45753 | D31: Broiler DOC | E31: 200 | F31: 856.96 | G31: 1.82 | H31: 168272.67 | I31: CHI FARMS | J31: 732.87 | K31: 146574 | L31: 3592.05 | M31: 1007.4 | N31: 11173.81 | O31: 162347.26 | P31: 21698.67 | Q31: 5925.41 | R31: Paid | S31: 168272.67 | T31: 0 | U31: Pending | V31: Phone Call | W31: Distributor | X31: Katsina | Y31: North West | Z31: 0.35 | AA31: =ROUND(H31-O31,2) -> 5925.41 | AB31: =AA31/H31 -> 0.035213145 | AC31: =ROUND(AA31-Q31,2) -> 0 | AD31: 2025 | AE31: 4 | AF31: April | AG31: 2025-04
A32: FZ00031 | B32: 45408 | C32: 45421 | D32: Broiler DOC | E32: 200 | F32: 890.13 | G32: 1.24 | H32: 175818.48 | I32: Farm Support | J32: 707.76 | K32: 141552 | L32: 4610.08 | M32: 602.92 | N32: 2749.04 | O32: 149514.04 | P32: 34266.48 | Q32: 26304.44 | R32: Paid | S32: 175818.48 | T32: 0 | U32: Collected | V32: Phone Call | W32: Smallholder Farmer | X32: Edo | Y32: South South | Z32: 1.91 | AA32: =ROUND(H32-O32,2) -> 26304.44 | AB32: =AA32/H32 -> 0.14961135 | AC32: =ROUND(AA32-Q32,2) -> 0 | AD32: 2024 | AE32: 4 | AF32: April | AG32: 2024-04
A33: FZ00032 | B33: 45933 | C33: 45946 | D33: Cockerel DOC | E33: 100 | F33: 787.71 | G33: 0.23 | H33: 78589.83 | I33: AgroPlus NG | J33: 545.51 | K33: 54551 | L33: 1211.32 | M33: 243.64 | N33: 5721.87 | O33: 61727.83 | P33: 24038.83 | Q33: 16862 | R33: Paid | S33: 78589.83 | T33: 0 | U33: Collected | V33: WhatsApp | W33: Smallholder Farmer | X33: Rivers | Y33: South South | Z33: 2.12 | AA33: =ROUND(H33-O33,2) -> 16862 | AB33: =AA33/H33 -> 0.21455702 | AC33: =ROUND(AA33-Q33,2) -> 0 | AD33: 2025 | AE33: 10 | AF33: October | AG33: 2025-10
A34: FZ00033 | B34: 45670 | D34: Noiler DOC | E34: 500 | F34: 968.28 | G34: 0.4 | H34: 0 | I34: Farm Support | J34: 803.36 | K34: 0 | L34: 0 | M34: 0 | N34: 0 | O34: 0 | P34: 0 | Q34: 0 | R34: Part-paid | S34: 0 | T34: 0 | U34: Cancelled | V34: WhatsApp | W34: Smallholder Farmer | X34: Kwara | Y34: North Central | Z34: 1.44 | AA34: =ROUND(H34-O34,2) -> 0 | AB34: =AA34/H34 -> #DIV/0! | AC34: =ROUND(AA34-Q34,2) -> 0 | AD34: 2025 | AE34: 1 | AF34: January | AG34: 2025-01
A35: FZ00034 | B35: 45629 | C35: 45636 | D35: Pullet DOC | E35: 250 | F35: 1429.02 | G35: 2.35 | H35: 348859.51 | I35: Farm Support | J35: 1055.83 | K35: 263957.5 | L35: 5068.41 | M35: 627.41 | N35: 11735.64 | O35: 281388.96 | P35: 84902.01 | Q35: 67470.55 | R35: Paid | S35: 348859.51 | T35: 0 | U35: Delivered | V35: Walk-in | W35: Smallholder Farmer | X35: Imo | Y35: South East | Z35: 2.41 | AA35: =ROUND(H35-O35,2) -> 67470.55 | AB35: =AA35/H35 -> 0.19340321 | AC35: =ROUND(AA35-Q35,2) -> 0 | AD35: 2024 | AE35: 12 | AF35: December | AG35: 2024-12
A36: FZ00035 | B36: 45728 | C36: 45730 | D36: Pullet DOC | E36: 250 | F36: 1388.55 | G36: 0.05 | H36: 346963.93 | I36: CHI FARMS | J36: 974.98 | K36: 243745 | L36: 4852 | M36: 1361.22 | N36: 204.04 | O36: 250162.26 | P36: 103218.93 | Q36: 96801.67 | R36: Part-paid | S36: 91678.99 | T36: 255284.94 | U36: Collected | V36: Reseller | W36: Smallholder Farmer | X36: Anambra | Y36: South East | Z36: 0.7 | AA36: =ROUND(H36-O36,2) -> 96801.67 | AB36: =AA36/H36 -> 0.27899635 | AC36: =ROUND(AA36-Q36,2) -> 0 | AD36: 2025 | AE36: 3 | AF36: March | AG36: 2025-03
A37: FZ00036 | B37: 46004 | C37: 46004 | D37: Turkey Poults | E37: 50 | F37: 2861.17 | G37: 0.04 | H37: 143001.28 | I37: Farm Support | J37: 2444.84 | K37: 122242 | L37: 636.35 | M37: 266.23 | N37: 1489.86 | O37: 124634.44 | P37: 20759.28 | Q37: 18366.84 | R37: Part-paid | S37: 99918.23 | T37: 43083.05 | U37: Delivered | V37: Referral | W37: Commercial Farm | X37: Bauchi | Y37: North East | Z37: 1.09 | AA37: =ROUND(H37-O37,2) -> 18366.84 | AB37: =AA37/H37 -> 0.12843829 | AC37: =ROUND(AA37-Q37,2) -> 0 | AD37: 2025 | AE37: 12 | AF37: December | AG37: 2025-12
A38: FZ00037 | B38: 45642 | C38: 45656 | D38: Noiler DOC | E38: 200 | F38: 988.4 | G38: 2.33 | H38: 193074.06 | I38: AgroPlus NG | J38: 728.18 | K38: 145636 | L38: 4584.32 | M38: 1057.6 | N38: 9535.89 | O38: 160813.81 | P38: 47438.06 | Q38: 32260.25 | R38: Paid | S38: 193074.06 | T38: 0 | U38: Delivered | V38: WhatsApp | W38: Agro-dealer | X38: Oyo | Y38: South West | Z38: 0.9 | AA38: =ROUND(H38-O38,2) -> 32260.25 | AB38: =AA38/H38 -> 0.16708744 | AC38: =ROUND(AA38-Q38,2) -> 0 | AD38: 2024 | AE38: 12 | AF38: December | AG38: 2024-12
A39: FZ00038 | B39: 45641 | C39: 45641 | D39: Broiler DOC | E39: 200 | F39: 874.51 | G39: 0.8 | H39: 173502.78 | I39: CHI FARMS | J39: 696.36 | K39: 139272 | L39: 1103.83 | M39: 442.81 | N39: 4254.52 | O39: 145073.16 | P39: 34230.78 | Q39: 28429.62 | R39: Part-paid | S39: 101562.34 | T39: 71940.44 | U39: Delivered | V39: Social Media | W39: Smallholder Farmer | X39: Lagos | Y39: South West | Z39: 1.27 | AA39: =ROUND(H39-O39,2) -> 28429.62 | AB39: =AA39/H39 -> 0.16385686 | AC39: =ROUND(AA39-Q39,2) -> 0 | AD39: 2024 | AE39: 12 | AF39: December | AG39: 2024-12
A40: FZ00039 | B40: 45328 | D40: Noiler DOC | E40: 1000 | F40: 1004.83 | G40: 5 | H40: 954588.5 | I40: Farm Support | J40: 815.17 | K40: 815170 | L40: 15523.85 | M40: 5576.13 | N40: 3040.11 | O40: 839310.09 | P40: 139418.5 | Q40: 115278.41 | R40: Part-paid | S40: 760073.6 | T40: 194514.9 | U40: Pending | V40: Reseller | W40: Smallholder Farmer | X40: Jigawa | Y40: North West | Z40: 0.28 | AA40: =ROUND(H40-O40,2) -> 115278.41 | AB40: =AA40/H40 -> 0.12076241 | AC40: =ROUND(AA40-Q40,2) -> 0 | AD40: 2024 | AE40: 2 | AF40: February | AG40: 2024-02
...

Sheet Pivot Table
G1: Product_Type | H1: (All) | J1: Product_Type | K1: (All) | Y1: Product_Type | Z1: (All)
Y2: State | Z2: (All) | AO2: Product_Type | AP2: (All)
A3: Row Labels | B3: Sum of Unit_Selling_Price_NGN | G3: Row Labels | H3: Count of Quantity_Ordered | J3: Average of Unit_Selling_Price_NGN | K3: Column Labels | P3: Sum of Order_Year | Q3: Column Labels
A4: Abia | B4: 4110.44 | G4: Abia | H4: 41 | J4: Row Labels | K4: Supplier A | L4: Supplier B | M4: Supplier C | N4: Supplier D | O4: Grand Total | P4: Row Labels | Q4: Broiler DOC | R4: Cockerel DOC | S4: Noiler DOC | T4: Pullet DOC | U4: Turkey Poults | V4: Grand Total | Y4: Row Labels | Z4: Sum of Quantity_Ordered | AA4: Sum of Revenue_NGN | AB4: Sum of Net_Profit_NGN | AC4: Count of Order_ID | AE4: Count of Delivery_Status | AF4: Column Labels | AO4: Average of Quantity_Ordered | AP4: Column Labels | AW4: Sum of Quantity_Ordered | AX4: Column Labels
A5: Adamawa | B5: 1033.12 | G5: Adamawa | H5: 22 | J5: North Central | K5: 1051.0112 | L5: 1059.9676 | M5: 1088.1403 | N5: 969.26091 | O5: 1052.519 | P5: Abia | Q5: 38460 | S5: 18219 | T5: 22269 | U5: 4050 | V5: 82998 | Y5: Phone Call | Z5: 90300 | AA5: 88908967 | AB5: 14544651 | AC5: 246 | AE5: Row Labels | AF5: Broiler DOC | AG5: Cockerel DOC | AH5: Noiler DOC | AI5: Pullet DOC | AJ5: Turkey Poults | AK5: Grand Total | AO5: Row Labels | AP5: 2023 | AQ5: 2024 | AR5: 2025 | AS5: Grand Total | AW5: Row Labels | AX5: Broiler DOC | AY5: Cockerel DOC | AZ5: Noiler DOC | BA5: Pullet DOC | BB5: Turkey Poults | BC5: Grand Total
A6: Akwa Ibom | B6: 2943.95 | G6: Akwa Ibom | H6: 38 | J6: North East | K6: 1059.7776 | L6: 959.21533 | M6: 1087.6741 | N6: 1213.2288 | O6: 1062.4521 | P6: Adamawa | Q6: 26316 | S6: 8097 | T6: 8097 | U6: 2024 | V6: 44534 | Y6: Referral | Z6: 64700 | AA6: 65368251 | AB6: 10159358 | AC6: 197 | AE6: Abia | AF6: 19 | AH6: 9 | AI6: 11 | AJ6: 2 | AK6: 41 | AO6: North Central | AP6: 750 | AQ6: 335.18519 | AR6: 351.83486 | AS6: 347.26027 | AW6: Abia | AX6: 6100 | AZ6: 3700 | BA6: 4250 | BB6: 1000 | BC6: 15050
A7: Anambra | B7: 891.93 | G7: Anambra | H7: 46 | J7: North West | K7: 1230.0003 | L7: 1057.9494 | M7: 972.77714 | N7: 1083.8219 | O7: 1108.0228 | P7: Akwa Ibom | Q7: 44543 | R7: 4049 | S7: 10124 | T7: 12148 | U7: 6074 | V7: 76938 | Y7: Reseller | Z7: 79900 | AA7: 80708958 | AB7: 11901014 | AC7: 222 | AE7: Adamawa | AF7: 13 | AH7: 4 | AI7: 4 | AJ7: 1 | AK7: 22 | AO7: North East | AP7: 100 | AQ7: 329.23077 | AR7: 365.07937 | AS7: 344.96124 | AW7: Adamawa | AX7: 4250 | AZ7: 1450 | BA7: 950 | BB7: 250 | BC7: 6900
A8: Bauchi | B8: 937.99 | G8: Bauchi | H8: 25 | J8: South East | K8: 1052.624 | L8: 988.85304 | M8: 1149.079 | N8: 1031.0628 | O8: 1053.6482 | P8: Anambra | Q8: 42516 | R8: 18221 | S8: 2024 | T8: 28341 | U8: 2024 | V8: 93126 | Y8: Social Media | Z8: 60850 | AA8: 59837675 | AB8: 9206774.1 | AC8: 190 | AE8: Akwa Ibom | AF8: 22 | AG8: 2 | AH8: 5 | AI8: 6 | AJ8: 3 | AK8: 38 | AO8: North West | AP8: 1000 | AQ8: 293.29897 | AR8: 368.30357 | AS8: 336.66667 | AW8: Akwa Ibom | AX8: 8550 | AY8: 350 | AZ8: 2500 | BA8: 1200 | BB8: 1300 | BC8: 13900
A9: Bayelsa | B9: 1010.36 | G9: Bayelsa | H9: 34 | J9: South South | K9: 1056.3318 | L9: 1060.2566 | M9: 1049.8051 | N9: 1084.6975 | O9: 1058.9101 | P9: Bauchi | Q9: 34418 | R9: 2024 | S9: 10123 | T9: 2024 | U9: 2025 | V9: 50614 | Y9: Walk-in | Z9: 52450 | AA9: 52085813 | AB9: 8653235.9 | AC9: 160 | AE9: Anambra | AF9: 21 | AG9: 9 | AH9: 1 | AI9: 14 | AJ9: 1 | AK9: 46 | AO9: South East | AP9: 275 | AQ9: 340.7563 | AR9: 347.0297 | AS9: 343.01802 | AW9: Anambra | AX9: 7150 | AY9: 1900 | AZ9: 250 | BA9: 5350 | BB9: 150 | BC9: 14800
A10: Benue | B10: 994.65 | G10: Benue | H10: 25 | J10: South West | K10: 1028.3791 | L10: 990.97049 | M10: 1052.1132 | N10: 1038.2829 | O10: 1022.5918 | P10: Bayelsa | Q10: 32394 | R10: 10122 | S10: 14174 | T10: 10123 | U10: 2025 | V10: 68838 | Y10: WhatsApp | Z10: 160450 | AA10: 1.6178002e+08 | AB10: 25044933 | AC10: 485 | AE10: Bauchi | AF10: 17 | AG10: 1 | AH10: 5 | AI10: 1 | AJ10: 1 | AK10: 25 | AO10: South South | AP10: 160 | AQ10: 295.34884 | AR10: 347.24771 | AS10: 320.25 | AW10: Bauchi | AX10: 6700 | AY10: 200 | AZ10: 2500 | BA10: 300 | BB10: 50 | BC10: 9750
A11: Delta | B11: 3932.55 | G11: Borno | H11: 18 | J11: Grand Total | K11: 1070.0709 | L11: 1018.7286 | M11: 1064.9925 | N11: 1058.6257 | O11: 1051.7883 | P11: Benue | Q11: 24294 | R11: 2024 | S11: 6074 | T11: 16197 | U11: 2025 | V11: 50614 | Y11: Grand Total | Z11: 508650 | AA11: 5.0868969e+08 | AB11: 79509966 | AC11: 1500 | AE11: Bayelsa | AF11: 16 | AG11: 5 | AH11: 7 | AI11: 5 | AJ11: 1 | AK11: 34 | AO11: South West | AP11: 1000 | AQ11: 351.27273 | AR11: 326.22951 | AS11: 340.76923 | AW11: Bayelsa | AX11: 6800 | AY11: 2000 | AZ11: 3400 | BA11: 1350 | BB11: 750 | BC11: 14300
A12: Ebonyi | B12: 2001.9 | G12: Cross River | H12: 38 | P12: Borno | Q12: 16197 | R12: 6073 | S12: 8098 | T12: 4050 | U12: 2025 | V12: 36443 | AE12: Benue | AF12: 12 | AG12: 1 | AH12: 3 | AI12: 8 | AJ12: 1 | AK12: 25 | AO12: Grand Total | AP12: 412.5 | AQ12: 331.46667 | AR12: 345.66396 | AS12: 339.1 | AW12: Benue | AX12: 4300 | AY12: 300 | AZ12: 1450 | BA12: 2500 | BB12: 750 | BC12: 9300
A13: Edo | B13: 1914.22 | G13: Delta | H13: 31 | P13: Cross River | Q13: 44541 | R13: 2024 | S13: 10122 | T13: 18219 | U13: 2025 | V13: 76931 | AE13: Borno | AF13: 8 | AG13: 3 | AH13: 4 | AI13: 2 | AJ13: 1 | AK13: 18 | AW13: Borno | AX13: 1850 | AY13: 800 | AZ13: 2100 | BA13: 450 | BB13: 750 | BC13: 5950
A14: Ekiti | B14: 2887.98 | G14: Ebonyi | H14: 57 | P14: Delta | Q14: 28342 | R14: 8098 | S14: 16194 | T14: 6074 | U14: 4049 | V14: 62757 | AE14: Cross River | AF14: 22 | AG14: 1 | AH14: 5 | AI14: 9 | AJ14: 1 | AK14: 38 | AW14: Cross River | AX14: 7150 | AY14: 50 | AZ14: 1450 | BA14: 2300 | BB14: 50 | BC14: 11000
A15: Enugu | B15: 1004.88 | G15: Edo | H15: 30 | P15: Ebonyi | Q15: 56685 | R15: 10122 | S15: 14172 | T15: 28342 | U15: 6074 | V15: 115395 | AE15: Delta | AF15: 14 | AG15: 4 | AH15: 8 | AI15: 3 | AJ15: 2 | AK15: 31 | AW15: Delta | AX15: 4800 | AY15: 450 | AZ15: 1200 | BA15: 1150 | BB15: 300 | BC15: 7900
A16: FCT Abuja | B16: 1922.87 | G16: Ekiti | H16: 92 | P16: Edo | Q16: 30366 | R16: 4049 | S16: 12145 | T16: 10122 | U16: 4049 | V16: 60731 | AE16: Ebonyi | AF16: 28 | AG16: 5 | AH16: 7 | AI16: 14 | AJ16: 3 | AK16: 57 | AW16: Ebonyi | AX16: 9050 | AY16: 1100 | AZ16: 1850 | BA16: 4200 | BB16: 700 | BC16: 16900
A17: Imo | B17: 2842.34 | G17: Enugu | H17: 43 | P17: Ekiti | Q17: 89077 | R17: 8097 | S17: 32392 | T17: 54660 | U17: 2024 | V17: 186250 | AE17: Edo | AF17: 15 | AG17: 2 | AH17: 6 | AI17: 5 | AJ17: 2 | AK17: 30 | AW17: Edo | AX17: 3950 | AY17: 200 | AZ17: 1150 | BA17: 1850 | BB17: 150 | BC17: 7300
A18: Jigawa | B18: 1864.86 | G18: FCT Abuja | H18: 35 | P18: Enugu | Q18: 42515 | R18: 10122 | S18: 8097 | T18: 24295 | U18: 2024 | V18: 87053 | AE18: Ekiti | AF18: 44 | AG18: 4 | AH18: 16 | AI18: 27 | AJ18: 1 | AK18: 92 | AW18: Ekiti | AX18: 16350 | AY18: 1700 | AZ18: 3800 | BA18: 9700 | BB18: 750 | BC18: 32300
A19: Kaduna | B19: 1007.93 | G19: Gombe | H19: 17 | P19: FCT Abuja | Q19: 32390 | R19: 4049 | S19: 10120 | T19: 22272 | U19: 2024 | V19: 70855 | AE19: Enugu | AF19: 21 | AG19: 5 | AH19: 4 | AI19: 12 | AJ19: 1 | AK19: 43 | AW19: Enugu | AX19: 8900 | AY19: 2100 | AZ19: 1700 | BA19: 3150 | BB19: 50 | BC19: 15900
A20: Katsina | B20: 1980.16 | G20: Imo | H20: 35 | P20: Gombe | Q20: 18221 | R20: 2024 | S20: 4049 | T20: 10121 | V20: 34415 | AE20: FCT Abuja | AF20: 16 | AG20: 2 | AH20: 5 | AI20: 11 | AJ20: 1 | AK20: 35 | AW20: FCT Abuja | AX20: 4800 | AY20: 1700 | AZ20: 1200 | BA20: 3850 | BB20: 50 | BC20: 11600
A21: Kwara | B21: 2983.49 | G21: Jigawa | H21: 37 | P21: Imo | Q21: 38463 | R21: 8098 | S21: 12147 | T21: 12147 | V21: 70855 | AE21: Gombe | AF21: 9 | AG21: 1 | AH21: 2 | AI21: 5 | AK21: 17 | AW21: Gombe | AX21: 1800 | AY21: 250 | AZ21: 1150 | BA21: 2650 | BC21: 5850
A22: Lagos | B22: 5762.38 | G22: Kaduna | H22: 35 | P22: Jigawa | Q22: 36439 | R22: 2025 | S22: 12145 | T22: 16195 | U22: 8099 | V22: 74903 | AE22: Imo | AF22: 19 | AG22: 4 | AH22: 6 | AI22: 6 | AK22: 35 | AW22: Imo | AX22: 8050 | AY22: 1650 | AZ22: 1250 | BA22: 2550 | BC22: 13500
A23: Nasarawa | B23: 1976.91 | G23: Kano | H23: 29 | P23: Kaduna | Q23: 28343 | R23: 10120 | S23: 10124 | T23: 22270 | V23: 70857 | AE23: Jigawa | AF23: 18 | AG23: 1 | AH23: 6 | AI23: 8 | AJ23: 4 | AK23: 37 | AW23: Jigawa | AX23: 6100 | AY23: 500 | AZ23: 3300 | BA23: 2250 | BB23: 1350 | BC23: 13500
A24: Ogun | B24: 4885.01 | G24: Katsina | H24: 31 | P24: Kano | Q24: 28346 | R24: 2025 | S24: 6075 | T24: 18223 | U24: 4050 | V24: 58719 | AE24: Kaduna | AF24: 14 | AG24: 5 | AH24: 5 | AI24: 11 | AK24: 35 | AW24: Kaduna | AX24: 4800 | AY24: 900 | AZ24: 1750 | BA24: 3450 | BC24: 10900
A25: Ondo | B25: 1941.21 | G25: Kebbi | H25: 23 | P25: Katsina | Q25: 28344 | R25: 4049 | S25: 10121 | T25: 16198 | U25: 4050 | V25: 62762 | AE25: Kano | AF25: 14 | AG25: 1 | AH25: 3 | AI25: 9 | AJ25: 2 | AK25: 29 | AW25: Kano | AX25: 6050 | AY25: 150 | AZ25: 450 | BA25: 3100 | BB25: 300 | BC25: 10050
A26: Osun | B26: 966.7 | G26: Kogi | H26: 37 | P26: Kebbi | Q26: 30365 | R26: 4049 | T26: 8099 | U26: 4050 | V26: 46563 | AE26: Katsina | AF26: 14 | AG26: 2 | AH26: 5 | AI26: 8 | AJ26: 2 | AK26: 31 | AW26: Katsina | AX26: 5200 | AY26: 250 | AZ26: 1950 | BA26: 3100 | BB26: 100 | BC26: 10600
A27: Oyo | B27: 5793.1 | G27: Kwara | H27: 33 | P27: Kogi | Q27: 42510 | S27: 6073 | T27: 26320 | V27: 74903 | AE27: Kebbi | AF27: 15 | AG27: 2 | AI27: 4 | AJ27: 2 | AK27: 23 | AW27: Kebbi | AX27: 5050 | AY27: 800 | BA27: 1350 | BB27: 1250 | BC27: 8450
A28: Plateau | B28: 4056.56 | G28: Lagos | H28: 88 | P28: Kwara | Q28: 30367 | R28: 4050 | S28: 18222 | T28: 12148 | U28: 2024 | V28: 66811 | AE28: Kogi | AF28: 21 | AH28: 3 | AI28: 13 | AK28: 37 | AW28: Kogi | AX28: 7850 | AZ28: 1250 | BA28: 2150 | BC28: 11250
A29: Rivers | B29: 1962.14 | G29: Nasarawa | H29: 28 | P29: Lagos | Q29: 103245 | R29: 16196 | S29: 28346 | T29: 28344 | U29: 2025 | V29: 178156 | AE29: Kwara | AF29: 15 | AG29: 2 | AH29: 9 | AI29: 6 | AJ29: 1 | AK29: 33 | AW29: Kwara | AX29: 5100 | AY29: 850 | AZ29: 3050 | BA29: 1400 | BB29: 150 | BC29: 10550
A30: Taraba | B30: 937.78 | G30: Niger | H30: 27 | P30: Nasarawa | Q30: 30369 | R30: 2024 | S30: 8099 | T30: 14172 | U30: 2024 | V30: 56688 | AE30: Lagos | AF30: 51 | AG30: 8 | AH30: 14 | AI30: 14 | AJ30: 1 | AK30: 88 | AW30: Lagos | AX30: 18550 | AY30: 2400 | AZ30: 3400 | BA30: 3350 | BB30: 150 | BC30: 27850
A31: Grand Total | B31: 64547.41 | G31: Ogun | H31: 90 | P31: Niger | Q31: 30364 | R31: 4049 | S31: 8097 | T31: 10124 | U31: 2025 | V31: 54659 | AE31: Nasarawa | AF31: 15 | AG31: 1 | AH31: 4 | AI31: 7 | AJ31: 1 | AK31: 28 | AW31: Nasarawa | AX31: 4800 | AY31: 250 | AZ31: 2250 | BA31: 3150 | BB31: 750 | BC31: 11200
G32: Ondo | H32: 72 | P32: Ogun | Q32: 95149 | R32: 10122 | S32: 30368 | T32: 44537 | U32: 2024 | V32: 182200 | AE32: Niger | AF32: 15 | AG32: 2 | AH32: 4 | AI32: 5 | AJ32: 1 | AK32: 27 | AW32: Niger | AX32: 5500 | AY32: 950 | AZ32: 1650 | BA32: 1500 | BB32: 250 | BC32: 9850
G33: Osun | H33: 75 | P33: Ondo | Q33: 64784 | R33: 20244 | S33: 14171 | T33: 42514 | U33: 4049 | V33: 145762 | AE33: Ogun | AF33: 47 | AG33: 5 | AH33: 15 | AI33: 22 | AJ33: 1 | AK33: 90 | AW33: Ogun | AX33: 16250 | AY33: 1400 | AZ33: 6200 | BA33: 6750 | BB33: 750 | BC33: 31350
G34: Oyo | H34: 103 | P34: Osun | Q34: 93127 | R34: 10123 | S34: 6074 | T34: 32392 | U34: 10123 | V34: 151839 | AE34: Ondo | AF34: 32 | AG34: 10 | AH34: 7 | AI34: 21 | AJ34: 2 | AK34: 72 | AW34: Ondo | AX34: 8550 | AY34: 3850 | AZ34: 1600 | BA34: 7600 | BB34: 150 | BC34: 21750
G35: Plateau | H35: 34 | P35: Oyo | Q35: 119442 | R35: 20243 | S35: 30368 | T35: 32391 | U35: 6072 | V35: 208516 | AE35: Osun | AF35: 46 | AG35: 5 | AH35: 3 | AI35: 16 | AJ35: 5 | AK35: 75 | AW35: Osun | AX35: 17000 | AY35: 1250 | AZ35: 400 | BA35: 5150 | BB35: 3000 | BC35: 26800
G36: Rivers | H36: 29 | P36: Plateau | Q36: 28342 | R36: 8097 | S36: 16197 | T36: 14172 | U36: 2025 | V36: 68833 | AE36: Oyo | AF36: 59 | AG36: 10 | AH36: 15 | AI36: 16 | AJ36: 3 | AK36: 103 | AW36: Oyo | AX36: 21600 | AY36: 3500 | AZ36: 5350 | BA36: 6000 | BB36: 700 | BC36: 37150
G37: Sokoto | H37: 29 | P37: Rivers | Q37: 28342 | R37: 6075 | S37: 14171 | T37: 8096 | U37: 2025 | V37: 58709 | AE37: Plateau | AF37: 14 | AG37: 4 | AH37: 8 | AI37: 7 | AJ37: 1 | AK37: 34 | AW37: Plateau | AX37: 5300 | AY37: 1900 | AZ37: 2200 | BA37: 2800 | BB37: 100 | BC37: 12300
G38: Taraba | H38: 23 | P38: Sokoto | Q38: 38464 | R38: 4049 | S38: 6074 | T38: 10122 | V38: 58709 | AE38: Rivers | AF38: 14 | AG38: 3 | AH38: 7 | AI38: 4 | AJ38: 1 | AK38: 29 | AW38: Rivers | AX38: 3950 | AY38: 550 | AZ38: 3000 | BA38: 1650 | BB38: 500 | BC38: 9650
G39: Yobe | H39: 24 | P39: Taraba | Q39: 26319 | R39: 2024 | S39: 2024 | T39: 12146 | U39: 4049 | V39: 46562 | AE39: Sokoto | AF39: 19 | AG39: 2 | AH39: 3 | AI39: 5 | AK39: 29 | AW39: Sokoto | AX39: 5100 | AY39: 1250 | AZ39: 500 | BA39: 1000 | BC39: 7850
G40: Zamfara | H40: 26 | P40: Yobe | Q40: 26318 | R40: 4050 | S40: 6074 | T40: 10123 | U40: 2025 | V40: 48590 | AE40: Taraba | AF40: 13 | AG40: 1 | AH40: 1 | AI40: 6 | AJ40: 2 | AK40: 23 | AW40: Taraba | AX40: 3250 | AY40: 150 | AZ40: 1000 | BA40: 2150 | BB40: 800 | BC40: 7350
...

Sheet FUTZAV Dashboard

Sheet Summary
A1: FUTZAV | Poultry Sales Analysis
A4: Metric | B4: Value | F4: Sales channel | G4: Orders | H4: Order share
A5: Orders | B5: =COUNTA('Poultry dataset'!A2:A1501) -> 1500 | F5: WhatsApp | G5: =COUNTIF('Poultry dataset'!$V$2:$V$1501,F5) -> 485 | H5: =G5/$B$5 -> 0.32333333
A6: Chicks ordered | B6: =SUM('Poultry dataset'!E2:E1501) -> 508650 | F6: Phone Call | G6: =COUNTIF('Poultry dataset'!$V$2:$V$1501,F6) -> 246 | H6: =G6/$B$5 -> 0.164
A7: Revenue (NGN) | B7: =SUM('Poultry dataset'!H2:H1501) -> 5.0868969e+08 | F7: Reseller | G7: =COUNTIF('Poultry dataset'!$V$2:$V$1501,F7) -> 222 | H7: =G7/$B$5 -> 0.148
A8: Net profit (NGN) | B8: =SUM('Poultry dataset'!AA2:AA1501) -> 79509966 | F8: Referral | G8: =COUNTIF('Poultry dataset'!$V$2:$V$1501,F8) -> 197 | H8: =G8/$B$5 -> 0.13133333
A9: Net profit source field (NGN) | B9: =SUM('Poultry dataset'!Q2:Q1501) -> 79509966 | F9: Social Media | G9: =COUNTIF('Poultry dataset'!$V$2:$V$1501,F9) -> 190 | H9: =G9/$B$5 -> 0.12666667
A10: Profit reconciliation (NGN) | B10: =SUM('Poultry dataset'!AC2:AC1501) -> 0 | F10: Walk-in | G10: =COUNTIF('Poultry dataset'!$V$2:$V$1501,F10) -> 160 | H10: =G10/$B$5 -> 0.10666667
A13: Product volume | B13: Chicks ordered | C13: Share of total | D13: Orders | F13: Region | G13: Chicks ordered | H13: Order count
A14: Broiler DOC | B14: =SUMIF('Poultry dataset'!$D$2:$D$1501,A14,'Poultry dataset'!$E$2:$E$1501) -> 269150 | C14: =B14/$B$6 -> 0.52914578 | D14: =COUNTIF('Poultry dataset'!$D$2:$D$1501,A14) -> 778 | F14: South West | G14: =SUMIF('Poultry dataset'!$Y$2:$Y$1501,F14,'Poultry dataset'!$E$2:$E$1501) -> 177200 | H14: =COUNTIF('Poultry dataset'!$Y$2:$Y$1501,F14) -> 520
A15: Pullet DOC | B15: =SUMIF('Poultry dataset'!$D$2:$D$1501,A15,'Poultry dataset'!$E$2:$E$1501) -> 110150 | C15: =B15/$B$6 -> 0.21655362 | D15: =COUNTIF('Poultry dataset'!$D$2:$D$1501,A15) -> 336 | F15: South East | G15: =SUMIF('Poultry dataset'!$Y$2:$Y$1501,F15,'Poultry dataset'!$E$2:$E$1501) -> 76150 | H15: =COUNTIF('Poultry dataset'!$Y$2:$Y$1501,F15) -> 222
A16: Noiler DOC | B16: =SUMIF('Poultry dataset'!$D$2:$D$1501,A16,'Poultry dataset'!$E$2:$E$1501) -> 72350 | C16: =B16/$B$6 -> 0.14223926 | D16: =COUNTIF('Poultry dataset'!$D$2:$D$1501,A16) -> 214 | F16: North Central | G16: =SUMIF('Poultry dataset'!$Y$2:$Y$1501,F16,'Poultry dataset'!$E$2:$E$1501) -> 76050 | H16: =COUNTIF('Poultry dataset'!$Y$2:$Y$1501,F16) -> 219
A17: Cockerel DOC | B17: =SUMIF('Poultry dataset'!$D$2:$D$1501,A17,'Poultry dataset'!$E$2:$E$1501) -> 37050 | C17: =B17/$B$6 -> 0.07283987 | D17: =COUNTIF('Poultry dataset'!$D$2:$D$1501,A17) -> 117 | F17: North West | G17: =SUMIF('Poultry dataset'!$Y$2:$Y$1501,F17,'Poultry dataset'!$E$2:$E$1501) -> 70700 | H17: =COUNTIF('Poultry dataset'!$Y$2:$Y$1501,F17) -> 210
A18: Turkey Poults | B18: =SUMIF('Poultry dataset'!$D$2:$D$1501,A18,'Poultry dataset'!$E$2:$E$1501) -> 19950 | C18: =B18/$B$6 -> 0.039221469 | D18: =COUNTIF('Poultry dataset'!$D$2:$D$1501,A18) -> 55 | F18: South South | G18: =SUMIF('Poultry dataset'!$Y$2:$Y$1501,F18,'Poultry dataset'!$E$2:$E$1501) -> 64050 | H18: =COUNTIF('Poultry dataset'!$Y$2:$Y$1501,F18) -> 200
F19: North East | G19: =SUMIF('Poultry dataset'!$Y$2:$Y$1501,F19,'Poultry dataset'!$E$2:$E$1501) -> 44500 | H19: =COUNTIF('Poultry dataset'!$Y$2:$Y$1501,F19) -> 129

Sheet DAX Measures
A3: Measure / object | B3: DAX expression | C3: Purpose
A4: Total Orders | B4: Total Orders = COUNTROWS('Sales') | C4: Number of order rows in current filter context
A5: Total Chicks Ordered | B5: Total Chicks Ordered = SUM('Sales'[Quantity_Ordered]) | C5: Ordered volume
A6: Total Revenue (NGN) | B6: Total Revenue (NGN) = SUM('Sales'[Revenue_NGN]) | C6: Revenue field total
A7: Total Cost (NGN) | B7: Total Cost (NGN) = SUM('Sales'[Total_Cost_NGN]) | C7: Total recorded cost
A8: Gross Profit (NGN) | B8: Gross Profit (NGN) = SUM('Sales'[Gross_Profit_NGN]) | C8: Gross profit field total
A9: Net Profit (NGN) | B9: Net Profit (NGN) = SUM('Sales'[Computed_Net_Profit_NGN]) | C9: Uses the calculated row-level column; matches slide total
A10: Source Net Profit (NGN) | B10: Source Net Profit (NGN) = SUM('Sales'[Net_Profit_NGN]) | C10: Reconciliation against source field
A11: Net Profit Reconciliation | B11: Net Profit Reconciliation (NGN) = [Net Profit (NGN)] - [Source Net Profit (NGN)] | C11: Should be 0
A12: Net Profit Margin | B12: Net Profit Margin = DIVIDE([Net Profit (NGN)], [Total Revenue (NGN)]) | C12: Net profit divided by revenue
A13: Outstanding Balance | B13: Outstanding Balance (NGN) = SUM('Sales'[Balance_Due_NGN]) | C13: Remaining customer balances
A14: Average Order Value | B14: Average Order Value (NGN) = DIVIDE([Total Revenue (NGN)], [Total Orders]) | C14: Average revenue per order row
... A22: Calendar month name | B22: Calendar Month = FORMAT(Calendar[Date], "MMMM") | C22: Calculated column in Calendar table
